<robot name="Fancy">
    <link name="base0">
    </link>
    <link name="link1">
        <inertial>
            <origin xyz="-0.50000 0.00000 0.00000"/>
            <mass value="1.00000"/>
            <inertia ixx="0.00250" iyy="0.08458" izz="0.08458" ixy="-0.00000" ixz="-0.00000" iyz="-0.00000"/>
        </inertial>
    </link>
    <link name="link2">
        <inertial>
            <origin xyz="-0.50000 0.00000 0.00000"/>
            <mass value="1.00000"/>
            <inertia ixx="0.00250" iyy="0.08458" izz="0.08458" ixy="-0.00000" ixz="-0.00000" iyz="-0.00000"/>
        </inertial>
    </link>
    <joint name="jA" type="revolute">
        <origin xyz="0.00000 0.00000 0.00000" rpy="3.141592653589793 1.570796282091413 3.141592653589793"/>
        <parent link="base0"/>
        <child  link="link1"/>
        <limit effort="30" velocity="1.0"/>
        <axis xyz="0 0 1"/>
    </joint>
    <joint name="jB" type="prismatic">
        <origin xyz="-1.00000 0.00000 0.00000" rpy="0.0 0.0 0.0"/>
        <parent link="link1"/>
        <child  link="link2"/>
        <limit effort="30" velocity="1.0"/>
        <axis xyz="0 0 1"/>
    </joint>
</robot>
